Workbook

Sheet 0_Návod
A1: PRAKTIK-AI | Matrice kurzu v7.0 | Návod pro metodika
A3: Jak pracovat s touto matricí
A5: Žluté buňky | B5: Buňky k vyplnění. Šedá kurzíva = nápověda / příklad — přepište svým obsahem.
A6: Modré klíče (levé sloupce) | B6: PEVNÉ identifikátory pro agenta. NEMĚŇTE jejich text — agent je čte jako klíče.
A7: Zelené listy (CIS_...) | B7: Číselníky. Read-only referenční data (neurovědní principy, formáty, KRAUU, role, pojmy). NEUPRAVUJTE bez vědomí garanta.
A8: Dropdowny | B8: Některé buňky mají rozbalovací seznam (ano/ne, Bloom úrovně, hodnotitel atd.) — použijte volby ze seznamu.
A9: Odkazování kódy | B9: Mezi listy odkazujte KÓDY (např. NP-08, FMT-MCQ, 2.4, ROLE-02), ne celým textem. Agent kódy spojuje napříč listy.
A10: Pořadí vyplňování (doporučené) | B10: 1) Identifikace (list 1, včetně 1.8 Parametry pro generátor) → 2) GOALS → 3) OBJECTIVES → 4) Větvení → 5–7) Principy a kompetence → 8) Vzory → 9) Artefakt → 10) Mediální přílohy → 11) Rubrika → 12) Výzkum → M1–M5, Capstone → 14) Zdroje → 13) Validace.
A11: Validace před odevzdáním | B11: Otevřete list 13_Validace. Sloupec Auto zezelená u splněných pravidel sám. Garant ručně potvrdí kvalitativní pravidla (GOAL je formulován správně, rubrika rozlišuje úrovně, vzory dávají smysl, žádný placeholder nezůstal).
A12: Struktura listů | B12: Listy 1–14 = data o kurzu (vyplňujete). Listy M1–M5 + Capstone = jednotlivé moduly. Listy CIS_* = číselníky (referenční), nově CIS_Skupiny a CIS_Urovne.
A14: 4 role uživatelů platformy:
A16: User | B16: Ten, kdo studuje kurz.
A17: Lektor | B17: Kontroluje výsledky studentů, poskytuje lidskou ZV, navrhuje a generuje kurzy.
A18: Garant | B18: Navrhuje vlastní kurzy a schvaluje cizí. Schvaluje validační checklist.
A19: Super admin | B19: Plný přístup ke všemu.
A21: Novinky ve verzi 7.0
A22: F1 PREZENTACE | B22: 5–10 minut (dříve max. 5). Délku určuje úroveň kurzu a náročnost tématu – viz list CIS_Urovne. F1 = výklad ke čtení („příručka").
A23: Úroveň (1.2) | B23: Tři úrovně zkušenosti s AI: Začátečník / Středně pokročilý / Pokročilý. Úroveň se týká práce s AI, ne odbornosti v oboru.
A24: Cílové skupiny | B24: Akademik (vč. doktorandů) · Student (Bc., Mgr.) · Mentor (provázející učitel ZŠ/SŠ). Definice pro generátor v listu CIS_Skupiny.
A25: 1.8 Parametry pro generátor | B25: Nový oddíl: cílové skupiny, počet modulů, anotace pro platformu (max. 500 znaků) a automatické převody pro generátor.
A26: Moduly M1–M5 | B26: Nová pole: Náročnost tématu, orientační rozsah F1, kontrola součtu fází, Otevřené problémy pro metodika (hlášení ⚠ PRO METODIKA z generátoru).
A27: 14_Zdroje | B27: Nový list: soubory ke kurzu s rolí (obsah / pravidla pro tvorbu / hotový kurz) a známé rozpory ve zdrojích. Generátor přijímá jen .md a .docx.
A28: 13_Validace | B28: Nové automatické kontroly (úroveň, cílové skupiny, anotace, F1 5–10 min, náročnost, otevřené problémy, zdroje) a dvě kvalitativní.
A29: Podklad změn | B29: Audit promptů generátoru kurzů, 25. 9. 2026 (simulace A0101, 12 variant).

Sheet 1_Identifikace
A1: PRAKTIK-AI | Matrice kurzu v7.0 | IDENTIFIKACE
A2: 💡 Žluté buňky = vyplňte. Modré klíče = NEMĚŇTE (čte je agent). Pole s rozbalovacím seznamem mají dropdown. Označení jako [NP-08] = kód z číselníku.
A4: 1.1 Identifikátory kurzu
A5: Interní kód (DB)
A6: Zobrazovací kód (UI)
A7: URL slug
A8: Plný název kurzu (certifikát)
A9: Řešený problém
A10: Výstup kurzu (artefakt)
A12: 1.2 Základní parametry
A13: Blok
A14: Verze kurzu
... A23: 1.3 Typ kurzu (lze více, zaškrtněte X)
B24: Obecný — platí pro všechny obory | D24: Oborový — specifický pro jeden obor
B25: Průřezový — přesahuje skupiny C | D25: Vstupní kurz skupiny (C bloky)
B26: Specializovaný — pro konkrétní roli | D26: Volitelné rozšíření
A28: 1.4 Anchor text a informační nota
A29: Anchor text
A30: Informační nota
A32: 1.5 Skip — pravidla přeskočení
A33: Skip povolen?
A34: Typ skipu
A35: Práh úspěšnosti (%)
A36: Při neúspěchu testu
A38: 1.6 Styl psaní a tón kurzu (zaškrtněte X)
B39: Konverzační — přímé oslovení uživatele (vykání) | D39: Narativní — situace, příběhy, dialogy z praxe
B40: Instruktážní — kroky a postupy v imperativu | D40: Analytický — systematický výklad (vhodné pro F1)
A41: Doplňující poznámka ke stylu
A42: Typické rozložení fází (min)
A44: 1.7 Text pro certifikát (shrnutí GOALS)
A45: Text certifikátu
A47: 1.8 Parametry pro generátor platformy (cílové skupiny zaškrtněte X)
B48: Akademik — vyučující, výzkumník, doktorand | D48: Student — Bc. a Mgr. studium (zejm. učitelství)
B49: Mentor — provázející učitel ZŠ/SŠ
A50: Počet modulů
A51: Minut na modul (auto) | B51: =IF(OR(B15="",B50=""),"",ROUND(B15/B50,0))
A52: Úroveň pro generátor (auto) | B52: =IF(B16="Začátečník","beginner",IF(B16="Středně pokročilý","intermediate",IF(B16="Pokročilý","advanced","")))
A53: Anotace pro platformu
A54: Anotace — počet znaků (auto) | B54: =IF(B53="","",LEN(B53)&" / 500")

Sheet 2_GOALS
A1: 2 GOALS — výkonové cíle kurzu
A2: 💡 GOALS = co absolvent kurzu prokazatelně zvládá. Sloveso 3. os. sg. + objekt + podmínka. Každý zaškrtnutý GOAL musí být zastoupen alespoň jednou fází modulu. Viz list 'CIS_Bloom' pro slovesa.
A4: ✓ | B4: Bloom úroveň | C4: Popis GOAL | D4: Pokryto v modulech
B5: 1 — Zapamatovat
B6: 2 — Porozumět
B7: 3 — Aplikovat
B8: 4 — Analyzovat
B9: 5 — Hodnotit
B10: 6 — Tvořit

Sheet 3_OBJECTIVES
A1: 3 OBJECTIVES — cíle modulů
A2: 💡 Každý OBJECTIVE = měřitelné chování (sloveso 3. os. sg. + objekt + podmínka). ID musí být UNIKÁTNÍ v rámci celého kurikula PRAKTIK-AI. Modul má 1–3 OBJECTIVES. Vazba na GOAL = úroveň Bloom z listu 2_GOALS.
A4: ID | B4: Text OBJECTIVE | C4: Typ | D4: Testovatelný? | E4: Modul č. | F4: Vazba na GOAL (Bloom úroveň)

Sheet 4_Vetveni
A1: 4 Větvení dle profilu uživatele
A2: 💡 Vyplňte, pokud se obsah kurzu výrazně liší dle role. Skupiny a jejich definice viz list CIS_Skupiny (větev „Učitel ZŠ/SŠ" ze starších podkladů patří pod Mentora). Per-modul větvení specifikujte v listech modulů.
A4: Modul č. | B4: Akademik (vč. doktorandů) | C4: Mentor (provázející učitel ZŠ/SŠ) | D4: Student (Bc., Mgr.)
A5: 1
A6: 2
A7: 3
A8: 4
A9: 5
A10: Capstone

Sheet 5_Neuroved_kurz
A1: 5 Neurovědní principy — globální výběr pro kurz
A2: 💡 Zaškrtněte (X) principy integrované v kurzu jako celku. Kompletní seznam s definicemi viz list 'CIS_Neuroveda'. Implementaci v konkrétním modulu uveďte v listu daného modulu.
A4: ✓ | B4: Kód | C4: Princip (CZ / EN) | D4: Stručně
B5: NP-01 | C5: Neuroplasticita / Neuroplasticity | D5: Mozek mění synapse podle zkušenosti — opakování přepisuje strukturu sítí.
B6: NP-02 | C6: Distribuované opakování / Spaced Repetition | D6: Rozložené učení trvá déle než nárazové.
B7: NP-03 | C7: Aktivní vybavování / Active Recall | D7: Vědomé vybavení posiluje paměť silněji než pasivní čtení.
B8: NP-04 | C8: Žádoucí obtíže / Desirable Difficulties | D8: Mírná obtížnost prohlubuje zpracování a transfer.
B9: NP-05 | C9: Prokládání / Interleaving | D9: Střídání úloh podporuje rozlišování konceptů a generalizaci.
B10: NP-06 | C10: Duální kódování / Dual Coding | D10: Text + vizuál = dvě paměťové stopy, lepší zapamatování.
B11: NP-07 | C11: Kognitivní zátěž / Cognitive Load Theory | D11: Pracovní paměť ~4±1 prvků; přetížení blokuje učení.
B12: NP-08 | C12: Elaborativní kódování / Elaborative Encoding | D12: Propojení s existujícími znalostmi tvoří hustou síť asociací.
B13: NP-09 | C13: Efekt generování / Generation Effect | D13: Sám vytvořená informace se pamatuje lépe než přijatá.
B14: NP-10 | C14: Testovací efekt / Testing Effect | D14: Testování samo o sobě konsoliduje dlouhodobou paměť.
B15: NP-11 | C15: Predikční chyba / Reward Prediction Error | D15: Překvapení (pozit. i negat.) řídí dopaminové učení.
B16: NP-12 | C16: Konsolidace ve spánku / Sleep-Dependent Consolidation | D16: Spánek přepisuje paměť z hipokampu do neokortexu.
... B24: NP-20 | C24: Schémata / Schema Theory | D24: Nové info se ukládá snáz, lze-li připojit ke schématu.

Sheet 6_AI_principy
A1: 6 AI principy kurzu
A2: 💡 Zaškrtněte (X) přístupy k AI, které kurz aktivně využívá nebo rozvíjí.
B4: AI jako partner v dialogu | D4: AI jako scaffold (podpora, ne náhrada)
B5: AI jako hodnotitel výstupu | D5: AI pro generování variant a alternativ
B6: AI pro personalizaci obsahu | D6: AI pro zpětnou vazbu v reálném čase
B7: Kritické hodnocení AI výstupů | D7: Prompt engineering jako dovednost
B8: Rozpoznání halucinací a ověřování | D8: Multimodalita (text + obraz + zvuk)
B9: Sokratovský dialog s AI | D9: AI jako zrcadlo pro reflexi

Sheet 7_KRAUU_kurz
A1: 7 KRAUU — kompetence pokryté kurzem
A2: 💡 Zaškrtněte (X) kompetence KRAUU, k jejichž rozvoji kurz přispívá. Mapování je interní — uživateli se nezobrazuje. Cílí primárně na Úroveň 1 (absolvent/ka). Kompletní seznam s popisy viz list 'CIS_KRAUU'.
A4: ✓ | B4: Kód | C4: Kompetence
B5: 1.1 | C5: Rozumí vyučovaným oborům a dále se v nich rozvíjí
B6: 1.2 | C6: Didakticky zprostředkovává obsah žákům
B7: 2.1 | C7: Nastavuje cíle výuky
B8: 2.2 | C8: Poznává vzdělávací potřeby a plánuje výuku
B9: 2.3 | C9: Podporuje zvídavost a motivaci žáků
B10: 2.4 | C10: Efektivně vede výuku a zjišťuje porozumění
B11: 2.5 | C11: Reflektuje výuku
B12: 3.1 | C12: Vytváří bezpečné prostředí pro učení
B13: 3.2 | C13: Vede žáky k chování podporujícímu učení
B14: 3.3 | C14: Uspořádání fyzického a digitálního prostředí
B15: 4.1 | C15: Hodnotí na základě kritérií
B16: 4.2 | C16: Poskytuje a přijímá zpětnou vazbu
... B22: 6.3 | C22: Duševní zdraví a psychohygiena

Sheet 8_Vzory_antipatterns
A1: 8 Vzory a antipatterns pro agenta
A2: 💡 Pravidla pro agenta. Typ = MUSÍ (pozitivní vzor) / NESMÍ (antipattern). Sloupec 'Kde' = globálně pro celý kurz, nebo číslo modulu.
A4: Typ | B4: Pravidlo (co agent MUSÍ/NESMÍ) | C4: Zdůvodnění (1–2 věty) | D4: Kde (modul / globálně)

Sheet 9_Artefakt
A1: 9 Finální artefakt kurzu
A2: 💡 ARTEFAKT je budován postupně přes F4 APLIKACE každého modulu. Badge je vázán na splnění finálního ověření (práh 75 %) + odevzdání artefaktu.
A4: 9.1 Definice artefaktu
A5: Typ artefaktu
A6: Co musí artefakt obsahovat
A7: Co artefakt nesmí obsahovat
A8: Primární formát pro odevzdání
A9: Vstupuje do databáze scénářů?
A10: Podmínka vydání badge
A11: Patří k mikrocertifikátu
A13: 9.2 Šablona artefaktu — povinné sekce
A14: 💡 Pokud má artefakt pevnou strukturu, popište povinné sekce. Agent předá uživateli jako pracovní dokument.
A15: # | B15: Sekce artefaktu | C15: Co sekce obsahuje | D15: Povinná?
A16: 1
A17: 2
A18: 3
A19: 4
A20: 5
A21: 6
A22: 7
A23: 8
A24: 9
A25: 10

Sheet 10_Medialni_prilohy
A1: 10 Mediální přílohy — grafika a audio
A2: ⚠ Pojmenování souborů: [KOD_KURZU]-[MODUL]-[TYP]-[popis].[přípona]. Příklady: A1-M2-audio-uvod.mp3 | A1-M1-grafika-tokenizace.png. Podporované formáty: PNG, SVG, MP3. Video zatím není podporováno.
A4: Název souboru | B4: Typ | C4: Modul č. | D4: Pozice v modulu (fáze) | E4: Alt text / popis | F4: Zdroj / licence | G4: Schválil

Sheet 11_Rubrika
A1: 11 Rubrika hodnocení (finální ověření)
A2: 💡 Rubrika hodnotí FINÁLNÍ artefakt kurzu. Max. 5 kritérií × 5 úrovní. Mapování na badge: Začátek 0–20 % | Rozvoj 21–40 % | Způsobilost 41–60 % | Zdatnost 61–80 % | Mistrovství 81–100 %. Práh pro badge = 75 % (horní polovina pásma Zdatnosti). ⚠ Názvy úrovní jsou závazné — neměňte je.
A4: 11.1 Nastavení rubriky
A5: Typ rubriky
A6: Hodnotitel
A7: Práh pro badge (%)
A9: 11.2 Tabulka 5 × 5 — kritéria a úrovně výkonu
A10: Kritérium hodnocení | B10: Mistrovství 81–100 % | C10: Zdatnost 61–80 % | D10: Způsobilost 41–60 % | E10: Rozvoj 21–40 % | F10: Začátek 0–20 % | G10: Váha kritéria (%)
A11: Kritérium 1
A12: Kritérium 2
A13: Kritérium 3
A14: Kritérium 4
A15: Kritérium 5
A17: 11.3 Doporučení navazujícího kurzu (pro routing agenta)
A18: Scénář | B18: Doporučení (kód kurzu + zdůvodnění 1 věta)
A19: Silný výkon (≥ 80 %)
A20: Slabý výkon (< 60 %)
A21: Mezera v konkrétní OBJECTIVE (uveďte ID)

Sheet 12_Vyzkum
A1: 12 Výzkumná poznámka
A2: 💡 Volitelné. Vyplňte, pokud kurz testuje specifickou hypotézu nebo sleduje proměnnou. Tato poznámka jde přímo výzkumnému týmu.
A4: Výzkumná hypotéza / sledovaná proměnná
A5: Pre-dotazník před zahájením kurzu
A6: Post-dotazník po dokončení kurzu
A7: Reflexivní poznámka uživatele k artefaktu

Sheet 13_Validace
A1: 13 Validační checklist
A2: 💡 Sloupec 'Auto' = automatická kontrola formátu (vzorec, zezelená/zčervená samo). Sloupec 'Garant' = ruční potvrzení kvality. Před odevzdáním musí být vše OK.
A4: # | B4: Kontrolované pravidlo | C4: Auto (vzorec) | D4: Garant (ruční) | E4: Poznámka garanta
A5: 1 | B5: 1.1 Interní kód (DB) je vyplněn | C5: =IF(1_Identifikace!B5="","CHYBĚJÍCÍ",IF(1_Identifikace!B5=1_Identifikace!B5,"OK","CHYBA"))
A6: 2 | B6: 1.1 Interní kód má formát písmeno + 4 číslice (např. A0101) | C6: =IF(1_Identifikace!B5="","CHYBĚJÍCÍ",IF(AND(LEN(1_Identifikace!B5)=5,ISNUMBER(VALUE(MID(1_Identifikace!B5,2,4)))),"OK","CHYBA FORMÁTU"))
A7: 3 | B7: 1.1 URL slug je vyplněn | C7: =IF(1_Identifikace!B7="","CHYBĚJÍCÍ","OK")
A8: 4 | B8: 1.1 URL slug neobsahuje mezery | C8: =IF(1_Identifikace!B7="","CHYBĚJÍCÍ",IF(ISERROR(FIND(" ",1_Identifikace!B7)),"OK","OBSAHUJE MEZERU"))
A9: 5 | B9: 1.1 Plný název kurzu je vyplněn | C9: =IF(1_Identifikace!B8="","CHYBĚJÍCÍ","OK")
A10: 6 | B10: 1.1 Řešený problém je vyplněn | C10: =IF(1_Identifikace!B9="","CHYBĚJÍCÍ","OK")
A11: 7 | B11: 1.2 EQF úroveň je vyplněna | C11: =IF(1_Identifikace!B18="","CHYBĚJÍCÍ","OK")
A12: 8 | B12: 1.2 Délka celkem (min) je vyplněna | C12: =IF(1_Identifikace!B15="","CHYBĚJÍCÍ","OK")
A13: 9 | B13: 1.4 Anchor text je vyplněn | C13: =IF(1_Identifikace!B29="","CHYBĚJÍCÍ","OK")
A14: 10 | B14: 1.4 Informační nota je vyplněna | C14: =IF(1_Identifikace!B30="","CHYBĚJÍCÍ","OK")
A15: 11 | B15: 1.7 Text certifikátu je vyplněn | C15: =IF(1_Identifikace!B45="","CHYBĚJÍCÍ","OK")
A16: 12 | B16: 2 Alespoň jeden GOAL má vyplněný popis | C16: =IF(COUNTA(2_GOALS!C5:C10)>0,"OK","ŽÁDNÝ GOAL NEVYPLNĚN")
A17: 13 | B17: 3 Alespoň jeden OBJECTIVE je vyplněn | C17: =IF(COUNTA(3_OBJECTIVES!A5:A24)>0,"OK","ŽÁDNÝ OBJECTIVE NEVYPLNĚN")
A18: 14 | B18: 3 ID OBJECTIVES jsou unikátní (kontrola duplicit) | C18: =IF(COUNTA(3_OBJECTIVES!A5:A24)=SUMPRODUCT((3_OBJECTIVES!A5:A24<>"")/COUNTIF(3_OBJECTIVES!A5:A24,3_OBJECTIVES!A5:A24&"")),"OK","DUPLICITNÍ ID")
A19: 15 | B19: 5 Alespoň jeden neurovědní princip je vybrán pro kurz | C19: =IF(COUNTIF(5_Neuroved_kurz!A5:A24,"X")>0,"OK","ŽÁDNÝ PRINCIP NEOZNAČEN")
A20: 16 | B20: 6 Alespoň jeden AI princip je vybrán | C20: =IF(COUNTIF(6_AI_principy!A4:A9,"X")+COUNTIF(6_AI_principy!C4:C9,"X")>0,"OK","ŽÁDNÝ AI PRINCIP")
A21: 17 | B21: 7 Alespoň jedna KRAUU kompetence je označena | C21: =IF(COUNTIF(7_KRAUU_kurz!A5:A22,"X")>0,"OK","ŽÁDNÁ KOMPETENCE")
A22: 18 | B22: 8 Alespoň jeden vzor / antipattern je vyplněn | C22: =IF(COUNTA(8_Vzory_antipatterns!A5:A19)>0,"OK","ŽÁDNÉ PRAVIDLO")
A23: 19 | B23: 9 Typ artefaktu je vyplněn | C23: =IF(9_Artefakt!B5="","CHYBĚJÍCÍ","OK")
A24: 20 | B24: 9 Co artefakt musí obsahovat je vyplněno | C24: =IF(9_Artefakt!B6="","CHYBĚJÍCÍ","OK")
A25: 21 | B25: 11.1 Hodnotitel rubriky je vybrán | C25: =IF(11_Rubrika!B6="","CHYBĚJÍCÍ","OK")
A26: 22 | B26: 11.2 Všech 5 kritérií rubriky je popsáno (sloupec Mistrovství) | C26: =IF(COUNTA(11_Rubrika!B11:B15)=5,"OK","NEKOMPLETNÍ")
A27: 23 | B27: 11.3 Doporučení pro silný výkon je vyplněno | C27: =IF(11_Rubrika!B19="","CHYBĚJÍCÍ","OK")
A28: 24 | B28: 11.3 Doporučení pro slabý výkon je vyplněno | C28: =IF(11_Rubrika!B20="","CHYBĚJÍCÍ","OK")
A29: 25 | B29: M1 Modul 1 má vyplněný název | C29: =IF(M1!B4="","CHYBĚJÍCÍ","OK")
A30: 26 | B30: M1 Modul 1 má vyplněný IMPULS | C30: =IF(M1!B6="","CHYBĚJÍCÍ","OK")
A31: 27 | B31: M2 Modul 2 má vyplněný název | C31: =IF(M2!B4="","CHYBĚJÍCÍ","OK")
A32: 28 | B32: M3 Modul 3 má vyplněný název | C32: =IF(M3!B4="","CHYBĚJÍCÍ","OK")
A33: 29 | B33: M4 Modul 4 má vyplněný název | C33: =IF(M4!B4="","CHYBĚJÍCÍ","OK")
A34: 30 | B34: M5 Modul 5 má vyplněný název | C34: =IF(M5!B4="","CHYBĚJÍCÍ","OK")
A35: 31 | B35: Capstone má zvolenou variantu (A nebo B) | C35: =IF(Capstone!B4="","CHYBĚJÍCÍ","OK")
A36: 32 | B36: KVALITA: GOAL je formulován slovesem 3. os. sg. + objekt + podmínka | C36: —
A37: 33 | B37: KVALITA: Každý zaškrtnutý GOAL je zastoupen alespoň jednou fází modulu | C37: —
A38: 34 | B38: KVALITA: Rubrika rozumně rozlišuje úrovně (popis kompetence, ne uživatele) | C38: —
A39: 35 | B39: KVALITA: Implementace neurovědních principů dává smysl v dané fázi | C39: —
A40: 36 | B40: KVALITA: IMPULS skutečně 'vtáhne' uživatele do tématu | C40: —
A41: 37 | B41: KVALITA: Vzory a antipatterns jsou konkrétní a aplikovatelné | C41: —
...

Sheet 14_Zdroje
A1: 14 Zdroje kurzu a jejich role
A2: 💡 Soubory, které nahrajete ke kurzu pro generátor. AI tvorba přijímá jen .md a .docx; obrázky (PNG, SVG) vkládáte ručně až do hotového kurzu (list 10). Role říká generátoru, jak soubor číst: Obsah = učivo · Pravidla pro tvorbu = pokyny, QA report, zápis rozhovoru (neučí se z nich) · Hotový kurz = osnova ke konverzi.
A4: Název souboru | B4: Formát | C4: Role | D4: Pro moduly | E4: Obsah / co z něj brát | F4: Ověřeno (fakta, zdroje) | G4: Poznámka
A27: Známé rozpory ve zdrojích
A28: Téma / tvrzení | B28: Zdroj A říká | C28: Zdroj B říká | D28: Platné znění (rozhodnutí autora)

Sheet M1
A1: MODUL 1
A2: 💡 OBJECTIVES (ID) odkazují na list 3_OBJECTIVES. Neurovědní princip = kód NP-XX z listu CIS_Neuroveda. Formát F2/F3 = kód FMT-XX z listu CIS_Formaty. F1 PREZENTACE 5–10 min podle úrovně a náročnosti (CIS_Urovne). F4 APLIKACE nelze přeskočit.
A4: Název modulu
A5: Délka modulu (min)
A6: IMPULS
A7: OBJECTIVES (ID)
A8: Skip povolen?
A9: Vazba na GOALS
A10: Větvení dle profilu
A12: F1 PREZENTACE (5–10 min podle úrovně a náročnosti, začíná IMPULSEM)
A13: Délka F1 (min)
A14: F1 — Obsah výkladu
... A40: Náročnost tématu
A41: Orientační rozsah F1 (auto) | B41: =IF(OR('1_Identifikace'!$B$16="",B40=""),"",IFERROR(INDEX(CIS_Urovne!$E$5:$E$10,MATCH('1_Identifikace'!$B$16&"|"&IF(B40="vysoká","vysoká","běžná"),CIS_Urovne!$H$5:$H$10,0))&" min (≈ "&INDEX(CIS_Urovne!$F$5:$F$10,MATCH('1_Identifikace'!$B$16&"|"&IF(B40="vysoká","vysoká","běžná"),CIS_Urovne!$H$5:$H$10,0))&" slov)",""))
A42: Kontrola součtu fází (auto) | B42: =IF(OR(B5="",B13=""),"",IF(B13+B17+B22+B27=B5,"OK","SOUČET "&(B13+B17+B22+B27)&" ≠ "&B5))
A43: Otevřené problémy pro metodika

Sheet M2
A1: MODUL 2
A2: 💡 OBJECTIVES (ID) odkazují na list 3_OBJECTIVES. Neurovědní princip = kód NP-XX z listu CIS_Neuroveda. Formát F2/F3 = kód FMT-XX z listu CIS_Formaty. F1 PREZENTACE 5–10 min podle úrovně a náročnosti (CIS_Urovne). F4 APLIKACE nelze přeskočit.
A4: Název modulu
A5: Délka modulu (min)
A6: IMPULS
A7: OBJECTIVES (ID)
A8: Skip povolen?
A9: Vazba na GOALS
A10: Větvení dle profilu
A12: F1 PREZENTACE (5–10 min podle úrovně a náročnosti, začíná IMPULSEM)
A13: Délka F1 (min)
A14: F1 — Obsah výkladu
... A40: Náročnost tématu
A41: Orientační rozsah F1 (auto) | B41: =IF(OR('1_Identifikace'!$B$16="",B40=""),"",IFERROR(INDEX(CIS_Urovne!$E$5:$E$10,MATCH('1_Identifikace'!$B$16&"|"&IF(B40="vysoká","vysoká","běžná"),CIS_Urovne!$H$5:$H$10,0))&" min (≈ "&INDEX(CIS_Urovne!$F$5:$F$10,MATCH('1_Identifikace'!$B$16&"|"&IF(B40="vysoká","vysoká","běžná"),CIS_Urovne!$H$5:$H$10,0))&" slov)",""))
A42: Kontrola součtu fází (auto) | B42: =IF(OR(B5="",B13=""),"",IF(B13+B17+B22+B27=B5,"OK","SOUČET "&(B13+B17+B22+B27)&" ≠ "&B5))
A43: Otevřené problémy pro metodika

Sheet M3
A1: MODUL 3
A2: 💡 OBJECTIVES (ID) odkazují na list 3_OBJECTIVES. Neurovědní princip = kód NP-XX z listu CIS_Neuroveda. Formát F2/F3 = kód FMT-XX z listu CIS_Formaty. F1 PREZENTACE 5–10 min podle úrovně a náročnosti (CIS_Urovne). F4 APLIKACE nelze přeskočit.
A4: Název modulu
A5: Délka modulu (min)
A6: IMPULS
A7: OBJECTIVES (ID)
A8: Skip povolen?
A9: Vazba na GOALS
A10: Větvení dle profilu
A12: F1 PREZENTACE (5–10 min podle úrovně a náročnosti, začíná IMPULSEM)
A13: Délka F1 (min)
A14: F1 — Obsah výkladu
... A40: Náročnost tématu
A41: Orientační rozsah F1 (auto) | B41: =IF(OR('1_Identifikace'!$B$16="",B40=""),"",IFERROR(INDEX(CIS_Urovne!$E$5:$E$10,MATCH('1_Identifikace'!$B$16&"|"&IF(B40="vysoká","vysoká","běžná"),CIS_Urovne!$H$5:$H$10,0))&" min (≈ "&INDEX(CIS_Urovne!$F$5:$F$10,MATCH('1_Identifikace'!$B$16&"|"&IF(B40="vysoká","vysoká","běžná"),CIS_Urovne!$H$5:$H$10,0))&" slov)",""))
A42: Kontrola součtu fází (auto) | B42: =IF(OR(B5="",B13=""),"",IF(B13+B17+B22+B27=B5,"OK","SOUČET "&(B13+B17+B22+B27)&" ≠ "&B5))
A43: Otevřené problémy pro metodika

Sheet M4
A1: MODUL 4
A2: 💡 OBJECTIVES (ID) odkazují na list 3_OBJECTIVES. Neurovědní princip = kód NP-XX z listu CIS_Neuroveda. Formát F2/F3 = kód FMT-XX z listu CIS_Formaty. F1 PREZENTACE 5–10 min podle úrovně a náročnosti (CIS_Urovne). F4 APLIKACE nelze přeskočit.
A4: Název modulu
A5: Délka modulu (min)
A6: IMPULS
A7: OBJECTIVES (ID)
A8: Skip povolen?
A9: Vazba na GOALS
A10: Větvení dle profilu
A12: F1 PREZENTACE (5–10 min podle úrovně a náročnosti, začíná IMPULSEM)
A13: Délka F1 (min)
A14: F1 — Obsah výkladu
... A40: Náročnost tématu
A41: Orientační rozsah F1 (auto) | B41: =IF(OR('1_Identifikace'!$B$16="",B40=""),"",IFERROR(INDEX(CIS_Urovne!$E$5:$E$10,MATCH('1_Identifikace'!$B$16&"|"&IF(B40="vysoká","vysoká","běžná"),CIS_Urovne!$H$5:$H$10,0))&" min (≈ "&INDEX(CIS_Urovne!$F$5:$F$10,MATCH('1_Identifikace'!$B$16&"|"&IF(B40="vysoká","vysoká","běžná"),CIS_Urovne!$H$5:$H$10,0))&" slov)",""))
A42: Kontrola součtu fází (auto) | B42: =IF(OR(B5="",B13=""),"",IF(B13+B17+B22+B27=B5,"OK","SOUČET "&(B13+B17+B22+B27)&" ≠ "&B5))
A43: Otevřené problémy pro metodika

Sheet M5
A1: MODUL 5
A2: 💡 OBJECTIVES (ID) odkazují na list 3_OBJECTIVES. Neurovědní princip = kód NP-XX z listu CIS_Neuroveda. Formát F2/F3 = kód FMT-XX z listu CIS_Formaty. F1 PREZENTACE 5–10 min podle úrovně a náročnosti (CIS_Urovne). F4 APLIKACE nelze přeskočit.
A4: Název modulu
A5: Délka modulu (min)
A6: IMPULS
A7: OBJECTIVES (ID)
A8: Skip povolen?
A9: Vazba na GOALS
A10: Větvení dle profilu
A12: F1 PREZENTACE (5–10 min podle úrovně a náročnosti, začíná IMPULSEM)
A13: Délka F1 (min)
A14: F1 — Obsah výkladu
... A40: Náročnost tématu
A41: Orientační rozsah F1 (auto) | B41: =IF(OR('1_Identifikace'!$B$16="",B40=""),"",IFERROR(INDEX(CIS_Urovne!$E$5:$E$10,MATCH('1_Identifikace'!$B$16&"|"&IF(B40="vysoká","vysoká","běžná"),CIS_Urovne!$H$5:$H$10,0))&" min (≈ "&INDEX(CIS_Urovne!$F$5:$F$10,MATCH('1_Identifikace'!$B$16&"|"&IF(B40="vysoká","vysoká","běžná"),CIS_Urovne!$H$5:$H$10,0))&" slov)",""))
A42: Kontrola součtu fází (auto) | B42: =IF(OR(B5="",B13=""),"",IF(B13+B17+B22+B27=B5,"OK","SOUČET "&(B13+B17+B22+B27)&" ≠ "&B5))
A43: Otevřené problémy pro metodika

Sheet Capstone
A1: CAPSTONE / Závěrečný modul
A2: 💡 Volba autora: (A) Vlastní F1–F4 blok (zjednodušený), nebo (B) Pouze finální ověření přes rubriku. Capstone propojuje výstupy F4 APLIKACE z modulů 1–5 do finálního artefaktu.
A4: Varianta capstone
A5: Název závěrečného modulu
A6: Délka (min)
A7: Obsah
A8: Vazba na artefakt
A10: Varianta A — zjednodušený F1–F4 blok (vyplňte pouze pokud Varianta = A)
A11: F1 — Obsah výkladu
A12: F2 — Aktivita
A13: F3 — Ověření
A14: F4 — Finální artefakt

Sheet CIS_Neuroveda
A1: ČÍSELNÍK | Neurovědní principy učení (20)
A2: 📘 Referenční číselník — read-only pro agenta i metodika. Odkazujte na principy kódem (NP-XX) v listech modulů. NEMĚŇTE názvy ani kódy.
A4: Kód | B4: Princip (CZ) | C4: Princip (EN) | D4: Stručný popis | E4: Příklad využití při učení s AI
A5: NP-01 | B5: Neuroplasticita | C5: Neuroplasticity | D5: Schopnost mozku přetvářet synaptické spoje na základě zkušenosti; opakované učení doslova mění strukturu nervových sítí. | E5: Pravidelné dialogy s AI nad jedním tématem (např. denní debata o ML konceptech) postupně utvářejí stabilní expertní okruhy.
A6: NP-02 | B6: Distribuované opakování | C6: Spaced Repetition | D6: Učení rozložené v čase vede k trvalejšímu zapamatování než nárazové studium díky opakovanému přepisování paměťové stopy. | E6: AI plánuje Anki-styl připomínky (1 den, 3 dny, 7 dní, 21 dní) na klíčové pojmy z předchozí konverzace.
A7: NP-03 | B7: Aktivní vybavování | C7: Active Recall / Retrieval Practice | D7: Vědomé vybavování informace z paměti posiluje paměťovou stopu výrazně více než pasivní opětovné čtení. | E7: AI nevykládá rovnou odpověď, ale vede uživatele sokratovskými otázkami: „Co si myslíš, že se stane, když…?
A8: NP-04 | B8: Žádoucí obtíže | C8: Desirable Difficulties | D8: Mírná obtížnost a kognitivní zápas při učení (Bjork) prohlubují zpracování a vedou k lepšímu transferu znalostí. | E8: AI postupně zvyšuje náročnost úloh, místo aby okamžitě poskytla zjednodušené řešení.
A9: NP-05 | B9: Prokládání | C9: Interleaving | D9: Střídání různých typů úloh v rámci jednoho cvičení podporuje rozlišování konceptů a generalizaci. | E9: AI při procvičování matematiky míchá derivace, integrály a limity místo blokového řešení jednoho typu.
A10: NP-06 | B10: Duální kódování | C10: Dual Coding | D10: Kombinace verbální a vizuální reprezentace (Paivio) vytváří dvě paměťové stopy a zlepšuje zapamatování. | E10: AI doplní textové vysvětlení diagramem, schématem nebo ASCII vizualizací procesu.
A11: NP-07 | B11: Kognitivní zátěž | C11: Cognitive Load Theory | D11: Pracovní paměť má kapacitu cca 4±1 prvků; přetížení blokuje učení. Je třeba rozdělit obsah na zvládnutelné kroky. | E11: AI rozloží komplexní úlohu (např. návrh API) do dílčích kroků a neřeší vše naráz.
A12: NP-08 | B12: Elaborativní kódování | C12: Elaborative Encoding | D12: Propojení nové informace s již existujícími znalostmi tvoří hustší síť asociací a usnadňuje budoucí vybavení. | E12: AI se ptá: „K čemu z toho, co už znáš, by se to dalo přirovnat?“ a buduje analogie.
A13: NP-09 | B13: Efekt generování | C13: Generation Effect | D13: Informace, kterou si člověk sám vytvoří či odvodí, se pamatuje lépe než pasivně přijatá. | E13: AI vyzve uživatele k prvnímu pokusu o řešení, teprve pak komentuje a opraví.
A14: NP-10 | B14: Testovací efekt | C14: Testing Effect | D14: Samotné testování (nikoli jen studium) je silným nástrojem konsolidace dlouhodobé paměti. | E14: AI po každé lekci generuje krátký kvíz nebo praktickou úlohu k ověření porozumění.
A15: NP-11 | B15: Predikční chyba | C15: Reward Prediction Error | D15: Dopaminový systém reaguje na rozdíl mezi očekáváním a realitou; překvapení (pozitivní i negativní) řídí učení (Schultz). | E15: AI nechá uživatele hádat výsledek experimentu před jeho odhalením — překvapení posílí zapamatování.
... A24: NP-20 | B24: Schémata | C24: Schema Theory | D24: Znalosti jsou v paměti organizovány do schémat; nové informace se snáze ukládají, lze-li je připojit k existujícímu schématu. | E24: AI pomáhá tvořit pojmové mapy a hierarchie, do nichž se postupně doplňují další detaily.

Sheet CIS_Formaty
A1: ČÍSELNÍK | Formáty interakce F2/F3 a finální ověření (13)
A2: 📘 Referenční číselník — read-only. Odkazujte na formáty kódem (FMT-XX) v listech modulů. Rubrika a Artefakt jsou určeny POUZE pro finální ověření.
A4: Kód | B4: Kategorie | C4: Název formátu | D4: Popis | E4: Role AI | F4: Náročnost IT
A5: FMT-MCQ | B5: Uzavřený | C5: Multiple choice | D5: Výběr z možností; testuje faktografii a porozumění konceptům. | E5: Generátor + hodnotitel | F5: Nízká
A6: FMT-TF | B6: Uzavřený | C6: True / false | D6: Pravda / nepravda; rychlé ověření klíčových tvrzení. | E6: Generátor + hodnotitel | F6: Nízká
A7: FMT-MTC | B7: Uzavřený | C7: Matching | D7: Párování pojmů s definicemi nebo příklady. | E7: Generátor + hodnotitel | F7: Nízká
A8: FMT-SA | B8: Uzavřený | C8: Short answer | D8: Krátká otevřená odpověď; testuje porozumění vlastními slovy. | E8: Hodnotitel odpovědi | F8: Nízká
A9: FMT-SOK | B9: Dialogický | C9: Sokratovský dialog s AI | D9: AI vede uživatele otázkami k vlastnímu závěru; nevyřkne odpověď přímo. | E9: Partner v dialogu | F9: Střední
A10: FMT-OTA | B10: Dialogický | C10: Tvorba otázek k tématu | D10: Uživatel formuluje 3 otázky k tématu; AI posoudí přesnost a hloubku. | E10: Posuzovatel formulace | F10: Nízká
A11: FMT-PRO | B11: Dialogický | C11: Protiargument | D11: Uživatel vytvoří protiargument k tvrzení; AI reaguje a rozvíjí diskusi. | E11: Diskutér | F11: Střední
A12: FMT-REF | B12: Dialogický | C12: Reflexe přinesené práce | D12: Uživatel přinese vlastní výstup; AI klade reflektivní otázky. Pouze F2/F3 nebo průběžné — ne finální ověření. | E12: Diskutér nad prací | F12: Nízká
A13: FMT-VLA | B13: Dialogický | C13: Vlastní formulace před AI verzí | D13: Uživatel nejprve vytvoří vlastní verzi, pak vidí AI/vzor a porovná. | E13: Konzultant, ne arbitr | F13: Nízká
A14: FMT-MIK | B14: Komplexní | C14: Mikroartefakt | D14: Krátký tvůrčí výstup (věta, definice, mikroscénář). AI navrhne zlepšení, uživatel rozhodne. | E14: Konzultant, ne arbitr | F14: Střední
A15: FMT-RUB | B15: Komplexní (finální) | C15: Rubrika | D15: Vícekriteriální hodnocení; sebehodnocení / AI / lektor / garant / kombinace — volba autora kurzu. | E15: Posuzovatel podle kritérií | F15: Střední
... A17: FMT-JIN | B17: Otevřený | C17: Jiné | D17: Volný formát mimo katalog. Popište přesně v poli 'Konkrétní znění / instrukce'. | E17: Dle popisu | F17: Dle popisu

Sheet CIS_Skupiny
A1: ČÍSELNÍK | Cílové skupiny kurzů (3)
A2: 📘 Referenční číselník — read-only. Sloupec „Definice pro generátor" čte generátor kurzů jako DEFINICE CÍLOVÉ SKUPINY. Úroveň pokročilosti se týká zkušenosti s AI, ne odbornosti v oboru. Skupina THP a Host zatím mimo číselník.
A4: Kód | B4: Skupina | C4: Popis do katalogu | D4: Větve ve starších podkladech | E4: Definice pro generátor (prompt_definition)
A5: a | B5: Akademik | C5: Akademický pracovník VŠ – vyučující, výzkumník, doktorand | D5: Akademik / doktorand | E5: Akademik: akademický pracovník vysoké školy – vyučující, výzkumník nebo doktorand (Ph.D.). Typické pracovní situace: příprava a vedení výuky; zadávání a hodnocení studentských prací; vedení a oponování závěrečných prací; výzkum, analýza dat a rešerše; psaní odborných textů, grantových přihlášek a posudků; recenzní řízení. Doktorand je zároveň studující: kromě výzkumu a výuky se ho týká i disertační práce a její deklarace využití AI. Pravidla, která se na skupinu vztahují: vnitřní předpisy univerzity v části pro vyučující a zaměstnance, publikační etika, pravidla časopisů a poskytovatelů grantů. Pravidla pro studentské práce na akademiky nepřenášej; výjimkou je disertační práce doktoranda. Oslovení: vykání; osobu neoznačuj rodově – piš „vyučující", případně popisem činnosti („ve výzkumu", „při vedení práce", „v disertaci"). Odborný akademický jazyk je přiměřený na každé úrovni – úroveň pokročilosti se týká zkušenosti s AI, ne odbornosti v oboru.
A6: s | B6: Student | C6: Student bakalářského nebo magisterského studia (zejména učitelství) | D6: Student učitelství | E6: Student: student bakalářského nebo navazujícího magisterského studia, zejména učitelství. Typické pracovní situace: studium odborných textů; přednášky a semináře; seminární práce; bakalářská a diplomová práce; příprava na zkoušky; příprava hodin a reflexe na pedagogické praxi. Rozlišení stupňů: bakalářský – první samostatné čtení odborného textu, seminární a bakalářská práce, úvodní praxe; magisterský – diplomová práce, vlastní výzkumné šetření, souvislá praxe a samostatné vedení hodin. Příklady volte tak, aby se v nich našli studující obou stupňů, nebo stupeň výslovně uveďte. Pravidla, která se na skupinu vztahují: studijní a zkušební řád, vnitřní předpisy univerzity k užití AI ve studiu (pravidla pro studentské práce a deklarace využití AI), pravidla konkrétního předmětu uvedená v sylabu. Oslovení: vykání; v textu „studující". Nikdy „studente".
A7: m | B7: Mentor | C7: Provázející učitel na ZŠ nebo SŠ (mentor pedagogické praxe) | D7: Mentor / provázející (uvádějící) učitel; Učitel ZŠ/SŠ | E7: Mentor: provázející učitel na základní nebo střední škole, který vede studenty učitelství na pedagogické praxi a zároveň sám učí žáky. Typické pracovní situace: příprava a vedení vlastních hodin; zadání, testy a hodnocení pro žáky; rozbor a reflexe hodin studenta na praxi; formulace zpětné vazby a hodnocení praxe; komunikace s fakultou a s rodiči. Pravidla, která se na skupinu vztahují: pro vlastní výuku platí pravidla školy (školní řád, pokyny vedení, ochrana osobních údajů žáků). Vnitřní předpisy univerzity se na mentora zpravidla přímo nevztahují; platí ale pro výstupy studenta z praxe (reflexe, portfolio, výstupy do předmětu). Pokud zdroje vztah pravidel k mentorovi neřeší, uveď, že je třeba ho ověřit u školy nebo fakulty. Ochrana údajů: do AI nevkládat osobní údaje žáků ani hodnocení konkrétního studenta. Oslovení: vykání; v textu „mentor" nebo „provázející učitel". Svěřence označuj „student na praxi", žáky „žáci" – tyto skupiny nikdy nezaměňuj.

Sheet CIS_Urovne
A1: ČÍSELNÍK | Úrovně pokročilosti a délka F1
A2: 📘 Referenční číselník — read-only. Úroveň = zkušenost účastníka s AI. F1 = výklad ke čtení, 130 slov/min. Sloupec „Souhrn na téma" určuje limit souhrnu generátoru (počet modulů × hodnota + 2 000 znaků, max. 60 000).
A4: Úroveň | B4: Profil generátoru | C4: Úrovně platformy (difficulty) | D4: Náročnost tématu | E4: F1 (min) | F4: F1 (slov) | G4: Souhrn na téma (znaků) | H4: Klíč (nepřepisovat)
A5: Začátečník | B5: beginner | C5: complete_beginner, beginner | D5: nízká / střední | E5: 5 | F5: 600–700 | G5: 2500 | H5: Začátečník|běžná
A6: Začátečník | B6: beginner | C6: complete_beginner, beginner | D6: vysoká | E6: 6 | F6: 700–850 | G6: 2500 | H6: Začátečník|vysoká
A7: Středně pokročilý | B7: intermediate | C7: slightly_advanced, intermediate | D7: nízká / střední | E7: 7 | F7: 850–1 000 | G7: 3500 | H7: Středně pokročilý|běžná
A8: Středně pokročilý | B8: intermediate | C8: slightly_advanced, intermediate | D8: vysoká | E8: 8 | F8: 950–1 100 | G8: 3500 | H8: Středně pokročilý|vysoká
A9: Pokročilý | B9: advanced | C9: advanced, expert | D9: nízká / střední | E9: 9 | F9: 1 100–1 250 | G9: 5000 | H9: Pokročilý|běžná
A10: Pokročilý | B10: advanced | C10: advanced, expert | D10: vysoká | E10: 10 | F10: 1 250–1 400 | G10: 5000 | H10: Pokročilý|vysoká
A12: Profily úrovní
A13: Začátečník | B13: Kratší věty, každý pojem týkající se AI vysvětlen při prvním výskytu, nejvýše 3 nové pojmy na modul, nejdřív analogie, postupy v číslovaných krocích. Otázky: porozumění pojmu nebo principu; otevřená otázka = popis situace z vlastní práce.
A14: Středně pokročilý | B14: Základní pojmy jen připomenuty; těžiště v principech, důvodech a typických chybách; srovnání postupů. Otázky: aplikace na situaci; otevřená otázka = zdůvodněné rozhodnutí.
A15: Pokročilý | B15: Bez elementárního výkladu a analogií; hraniční případy, limity, síla důkazu, institucionální důsledky, protiargumenty, víc detailů. Otázky: distraktory na úrovni nuancí; otevřená otázka = argumentace s protiargumentem.

Sheet CIS_KRAUU
A1: ČÍSELNÍK | KRAUU — Kompetenční rámec absolventa učitelství (MŠMT 2023)
A2: 📘 Referenční číselník — read-only. 18 kompetencí v 6 oblastech. Pokrytí cílí primárně na Úroveň 1 (absolvent/ka). Interní mapování — uživateli se nezobrazuje.
A4: Kód | B4: Oblast | C4: Kompetence | D4: Popis
A5: 1.1 | B5: 1 Obsah a didaktika | C5: Rozumí vyučovaným oborům a dále se v nich rozvíjí | D5: Učitel/ka rozumí oborům, které vyučuje, a systematicky se v nich rozvíjí.
A6: 1.2 | B6: 1 Obsah a didaktika | C6: Didakticky zprostředkovává obsah žákům | D6: Zprostředkovává obsah žákům v souladu s jejich vzdělávacími potřebami.
A7: 2.1 | B7: 2 Plánování, vedení a reflexe výuky | C7: Nastavuje cíle výuky | D7: Stanovuje srozumitelné cíle a vede k jejich nastavování i žáky a žákyně.
A8: 2.2 | B8: 2 Plánování, vedení a reflexe výuky | C8: Poznává vzdělávací potřeby a plánuje výuku | D8: Plánuje výuku tak, aby každý žák mohl aktivně dosahovat stanovených cílů.
A9: 2.3 | B9: 2 Plánování, vedení a reflexe výuky | C9: Podporuje zvídavost a motivaci žáků | D9: Podporuje u žáků zvídavost a motivaci k učení.
A10: 2.4 | B10: 2 Plánování, vedení a reflexe výuky | C10: Efektivně vede výuku a zjišťuje porozumění | D10: Vede výuku efektivně, zjišťuje porozumění a reaguje na potřeby žáků.
A11: 2.5 | B11: 2 Plánování, vedení a reflexe výuky | C11: Reflektuje výuku | D11: Reflektuje vlastní výuku a vyhodnocuje dosahování cílů.
A12: 3.1 | B12: 3 Prostředí pro učení | C12: Vytváří bezpečné prostředí pro učení | D12: Vytváří fyzicky i psychicky bezpečné prostředí pro učení.
A13: 3.2 | B13: 3 Prostředí pro učení | C13: Vede žáky k chování podporujícímu učení | D13: Vede žáky k chování podporujícímu vlastní učení i spolupráci.
A14: 3.3 | B14: 3 Prostředí pro učení | C14: Uspořádání fyzického a digitálního prostředí | D14: Zajišťuje vhodné uspořádání fyzického a digitálního prostředí učení.
A15: 4.1 | B15: 4 Zpětná vazba a hodnocení | C15: Hodnotí na základě kritérií | D15: Hodnotí žáky na základě jasných kritérií a vede k tomu i žáky.
... A22: 6.3 | B22: 6 Profesní sebepojetí, rozvoj, etika a duševní zdraví | C22: Duševní zdraví a psychohygiena | D22: Systematicky pečuje o své duševní zdraví a psychohygienu.

Sheet CIS_Bloom
A1: ČÍSELNÍK | Bloomova taxonomie
A2: 📘 Slovesa pro formulaci GOALS a OBJECTIVES. Používejte 3. osobu singuláru.
A4: Úroveň | B4: Název | C4: Typická slovesa pro GOALS a OBJECTIVES
A5: 1 | B5: Zapamatovat | C5: vyjmenuje, popíše, identifikuje, rozpozná, zopakuje
A6: 2 | B6: Porozumět | C6: vysvětlí, shrne, klasifikuje, interpretuje, přeloží
A7: 3 | B7: Aplikovat | C7: použije, provede, řeší, demonstruje, implementuje
A8: 4 | B8: Analyzovat | C8: porovná, rozliší, zhodnotí strukturu, rozloží, prozkoumá
A9: 5 | B9: Hodnotit | C9: posoudí, obhájí, kriticky zhodnotí, doporučí, zdůvodní
A10: 6 | B10: Tvořit | C10: navrhne, sestaví, vytvoří, zkonstruuje, naplánuje

Sheet CIS_Role
A1: ČÍSELNÍK | Role uživatelů platformy PRAKTIK-AI
A2: 📘 Závazná terminologie pro popisování rolí v matricích a v agentových instrukcích.
A4: Kód | B4: Role | C4: Oprávnění | D4: Popis
A5: ROLE-01 | B5: User (student) | C5: Studuje kurz, odevzdává artefakt | D5: Ten, kdo studuje. Prochází kurz, plní fáze F1–F4, odevzdává finální artefakt, sbírá badge.
A6: ROLE-02 | B6: Lektor | C6: Kontroluje výsledky, poskytuje lidskou ZV, navrhuje a generuje kurzy | D6: Může kontrolovat výsledky studentů, poskytovat lidskou zpětnou vazbu, navrhovat a generovat kurzy. Neschvaluje kurzy ostatních.
A7: ROLE-03 | B7: Garant | C7: Navrhuje + schvaluje vlastní i cizí kurzy, ručí za kvalitu | D7: Může navrhovat své kurzy a schvalovat cizí kurzy. Hodnotí kvalitativní část validačního checklistu před nahráním matrice na platformu.
A8: ROLE-04 | B8: Super admin | C8: Plný přístup ke všemu | D8: Má přístup ke všem kurzům, uživatelům, číselníkům a systémovým nastavením platformy.

Sheet CIS_Pojmy
A1: ČÍSELNÍK | Pojmy a zkratky
A2: 📘 Referenční přehled systémových termínů a zkratek používaných v matrici a na platformě.
A4: Systémové termíny PRAKTIK-AI
A5: Termín | B5: Co znamená | C5: Kde v matrici / na platformě
A6: MATRICE | B6: Tento dokument — specifikace kurzu vyplňovaná metodikem. Vstup pro agenta-tvůrce. Není viditelná pro uživatele platformy. | C6: celý soubor
A7: GOALS | B7: Výkonové cíle celého kurzu formulované dle Bloomovy taxonomie. Co absolvent po kurzu zvládá. | C7: list 2_GOALS
A8: OBJECTIVES | B8: Dílčí výkonové cíle konkrétního modulu. Přispívají k naplnění GOALS. Modul má 1–3 OBJECTIVES. | C8: list 3_OBJECTIVES, listy M1–M5
A9: ARTEFAKT | B9: Konkrétní produkt, který účastník odevzdá na konci kurzu. Budován postupně přes F4 APLIKACE každého modulu. | C9: list 9_Artefakt
A10: SKIP-TEST | B10: Volitelný vstupní test modulu. Pokud účastník uspěje (≥ 80 %), modul přeskočí. Pouze deklarativní znalosti. | C10: list 1_Identifikace (1.5), listy M1–M5
A11: IMPULS | B11: Úvodní věta nebo otázka, která vtáhne účastníka do tématu na začátku F1 PREZENTACE. | C11: listy M1–M5
A12: KRAUU | B12: Kompetenční rámec absolventa a absolventky učitelství (MŠMT, 2023). Interní mapování — nezobrazuje se uživateli. | C12: list 7_KRAUU_kurz, CIS_KRAUU
A13: BADGE | B13: Digitální odznak vydaný po splnění finálního ověření ≥ 75 %. Open Badges 3.0 / Europass kompatibilní. | C13: list 9_Artefakt, 11_Rubrika
A14: RUBRIKA | B14: Vícekriteriální hodnoticí nástroj v sekci 11. Nastavuje tvůrce kurzu. Hodnotitel: User / Lektor / Garant / AI / Kombinace. | C14: list 11_Rubrika
A15: CAPSTONE | B15: Závěrečný modul kurzu. Volba autora: (A) vlastní F1–F4 blok zjednodušený, nebo (B) pouze finální ověření přes rubriku. | C15: list Capstone
A17: Fáze modulu (F1–F4)
A18: Zkratka | B18: Plný název | C18: Co se v této fázi děje
A19: F1 | B19: PREZENTACE | C19: Výklad ke čtení („příručka") — teorie, ozdrojovaný obsah, diferenciace dle role. 5–10 minut podle úrovně a náročnosti tématu (CIS_Urovne). Začíná IMPULSEM.
A20: F2 | B20: PROCVIČENÍ | C20: Praktická aktivita, dílna nebo interaktivní cvičení. Účastník si ověřuje nové znalosti v bezpečném prostředí.
A21: F3 | B21: OVĚŘENÍ | C21: Test nebo checkpoint — verifikuje pochopení OBJECTIVES daného modulu. Podklad pro SKIP-TEST.
A22: F4 | B22: APLIKACE | C22: Tvorba dílčího úseku ARTEFAKTU. Každý modul přidává jednu část finálního výstupu. NELZE PŘESKOČIT.
A24: Technické zkratky
A25: Zkratka | B25: Co znamená | C25: Poznámka
A26: DB | B26: Databáze — interní systém platformy | C26: Interní kód (DB) vidí jen backend.
A27: UI | B27: Uživatelské rozhraní (User Interface) | C27: Zobrazovací kód (UI) vidí účastník — platforma, certifikát, portfolio.
A28: URL slug | B28: Část webové adresy identifikující kurz | C28: Bez diakritiky, pomlčky místo mezer. Př. ai-jak-funguje
A29: EQF | B29: Evropský rámec kvalifikací (European Qualifications Framework) | C29: Úrovně 6–8 = vysokoškolské vzdělávání. Vydavatel certifikátů UJEP.
A30: ECTS | B30: Evropský kreditní systém (European Credit Transfer System) | C30: 1 ECTS ≈ 25–30 hodin práce.
A31: PNG / SVG | B31: Formáty grafických souborů | C31: PNG = rastrová. SVG = vektorová. Oba podporuje platforma.
A32: MP3 | B32: Formát zvukového souboru | C32: Audio nahrávky — např. export z NotebookLM pro účastníky s dyslexií.
